<mujoco model="jrf_tilting_board_component">
    <compiler angle="radian" autolimits="true"/>

    <default>
        <joint damping="2.0" armature="0.05"/>
        <geom density="700" condim="3" friction="1.0 0.015 0.015" solref="0.012 1" solimp="0.86 0.995 0.001"/>
    </default>

    <worldbody>
        <!-- Component copy of the passive spring-loaded board used in scene.xml. -->
        <body name="board_support" pos="0.30 0 0.08">
            <geom name="hinge_stand_left" type="box" pos="0 -0.11 -0.045" size="0.012 0.010 0.045" rgba="0.24 0.24 0.26 1" contype="0" conaffinity="0"/>
            <geom name="hinge_stand_right" type="box" pos="0 0.11 -0.045" size="0.012 0.010 0.045" rgba="0.24 0.24 0.26 1" contype="0" conaffinity="0"/>
            <geom name="hinge_axle_visual" type="cylinder" pos="0 0 0" size="0.012 0.13" axisangle="1 0 0 1.5707963" rgba="0.08 0.08 0.09 1" contype="0" conaffinity="0"/>
            <geom name="spring_anchor" type="sphere" pos="0.18 0 -0.07" size="0.012" rgba="0.90 0.18 0.12 1" contype="0" conaffinity="0"/>
            <geom name="spring_visual_1" type="capsule" fromto="0.14 0 -0.060 0.155 0 -0.085" size="0.003" rgba="0.90 0.18 0.12 1" contype="0" conaffinity="0"/>
            <geom name="spring_visual_2" type="capsule" fromto="0.155 0 -0.085 0.170 0 -0.055" size="0.003" rgba="0.90 0.18 0.12 1" contype="0" conaffinity="0"/>
            <geom name="spring_visual_3" type="capsule" fromto="0.170 0 -0.055 0.185 0 -0.085" size="0.003" rgba="0.90 0.18 0.12 1" contype="0" conaffinity="0"/>
            <geom name="spring_visual_4" type="capsule" fromto="0.185 0 -0.085 0.200 0 -0.060" size="0.003" rgba="0.90 0.18 0.12 1" contype="0" conaffinity="0"/>
            <geom name="damper_visual" type="capsule" fromto="0.22 0 -0.065 0.25 0 -0.035" size="0.005" rgba="0.12 0.12 0.14 1" contype="0" conaffinity="0"/>
        </body>
        <body name="board_base" pos="0.30 0 0.08">
            <joint name="board_hinge" type="hinge" axis="0 -1 0" range="-0.65 0.65" stiffness="20.0" damping="1.2"/>
            <geom name="board_geom" type="box" pos="0.30 0 0" size="0.30 0.085 0.015"
                  density="250" rgba="0.58 0.43 0.24 1" contype="1" conaffinity="1"/>
            <site name="board_hinge_site" pos="0 0 0.015" size="0.008" rgba="0.95 0.05 0.05 1"/>
            <site name="trajectory_dot_0" pos="0.14 -0.095 0.018" size="0.004" rgba="1.0 0.75 0.05 1"/>
            <site name="trajectory_dot_1" pos="0.18 -0.095 0.018" size="0.004" rgba="1.0 0.75 0.05 1"/>
            <site name="trajectory_dot_2" pos="0.22 -0.095 0.018" size="0.004" rgba="1.0 0.75 0.05 1"/>
            <site name="trajectory_dot_3" pos="0.26 -0.095 0.018" size="0.004" rgba="1.0 0.75 0.05 1"/>
            <site name="trajectory_dot_4" pos="0.30 -0.095 0.018" size="0.004" rgba="1.0 0.75 0.05 1"/>
            <site name="trajectory_dot_5" pos="0.34 -0.095 0.018" size="0.004" rgba="1.0 0.75 0.05 1"/>
            <site name="trajectory_dot_6" pos="0.38 -0.095 0.018" size="0.004" rgba="1.0 0.75 0.05 1"/>
            <site name="trajectory_dot_7" pos="0.42 -0.095 0.018" size="0.004" rgba="1.0 0.75 0.05 1"/>
            <site name="trajectory_dot_8" pos="0.46 -0.095 0.018" size="0.004" rgba="1.0 0.75 0.05 1"/>
            <site name="board_mid_surface" pos="0.30 0 0.015" size="0.008" rgba="0.05 0.05 0.95 1"/>
            <site name="board_end_surface" pos="0.60 0 0.015" size="0.008" rgba="0.05 0.80 0.05 1"/>
        </body>
    </worldbody>
</mujoco>
