<mujoco model="jrf_3r_robot_component">
    <compiler angle="radian" autolimits="true"/>

    <default>
        <joint damping="5.0" armature="0.05"/>
        <geom density="700" condim="3" friction="1.2 0.02 0.02" solref="0.045 1" solimp="0.65 0.96 0.01"/>
        <position kp="90" kv="22" ctrlrange="-3.14159 3.14159" forcerange="-120 120"/>
    </default>

    <worldbody>
        <!-- Component copy of the arm used in scene.xml; kept separate for inspection. -->
        <body name="base" pos="0 0 0.08">
            <geom name="base_mount" type="cylinder" size="0.045 0.025" axisangle="1 0 0 1.5707963" rgba="0.18 0.18 0.20 1" contype="0" conaffinity="0"/>
            <body name="link1" pos="0 0 0">
                <joint name="joint1" type="hinge" axis="0 -1 0" range="-2.85 2.85"/>
                <geom name="link1_geom" type="capsule" fromto="0 0 0 0.30 0 0" size="0.022" rgba="0.86 0.20 0.18 1" contype="0" conaffinity="0"/>
                <body name="link2" pos="0.30 0 0">
                    <joint name="joint2" type="hinge" axis="0 -1 0" range="-2.65 2.65"/>
                    <geom name="link2_geom" type="capsule" fromto="0 0 0 0.28 0 0" size="0.020" rgba="0.15 0.58 0.35 1" contype="0" conaffinity="0"/>
                    <body name="link3" pos="0.28 0 0">
                        <joint name="joint3" type="hinge" axis="0 -1 0" range="-2.65 2.65"/>
                        <geom name="link3_geom" type="capsule" fromto="0 0 0 0.18 0 0" size="0.018" rgba="0.16 0.30 0.78 1" contype="0" conaffinity="0"/>
                        <geom name="pen_geom" type="sphere" pos="0.18 0 0" size="0.010" density="1200" rgba="0.03 0.03 0.03 1" contype="1" conaffinity="1"/>
                        <site name="pen_tip" pos="0.18 0 0" size="0.006" rgba="1 0.85 0.05 1"/>
                    </body>
                </body>
            </body>
        </body>
    </worldbody>

    <actuator>
        <position name="act_joint1" joint="joint1"/>
        <position name="act_joint2" joint="joint2"/>
        <position name="act_joint3" joint="joint3"/>
    </actuator>
</mujoco>
